{
  "nbformat": 4,
  "nbformat_minor": 0,
  "metadata": {
    "colab": {
      "provenance": []
    },
    "kernelspec": {
      "name": "python3",
      "display_name": "Python 3"
    },
    "language_info": {
      "name": "python"
    }
  },
  "cells": [
    {
      "cell_type": "code",
      "execution_count": 1,
      "metadata": {
        "colab": {
          "base_uri": "https://localhost:8080/"
        },
        "id": "_5Oe8PfccrEG",
        "outputId": "7d3f13df-f57d-4c9a-f7a0-56b89dd7372c"
      },
      "outputs": [
        {
          "output_type": "stream",
          "name": "stdout",
          "text": [
            "Mounted at /content/drive\n"
          ]
        }
      ],
      "source": [
        "# Deteccao de faces com CNN (redes neurais convolucionais)\n",
        "from google.colab import drive\n",
        "drive.mount('/content/drive')\n",
        "\n",
        "from google.colab.patches import cv2_imshow"
      ]
    },
    {
      "cell_type": "code",
      "source": [
        "import cv2\n",
        "import dlib # lib mais utilizada em visao computacional"
      ],
      "metadata": {
        "id": "Zvlo7LepY3eC"
      },
      "execution_count": 2,
      "outputs": []
    },
    {
      "cell_type": "code",
      "source": [
        "imagem = cv2.imread('/content/drive/MyDrive/Visaﾌバ Computacional Guia Completo/Images/people2.jpg')\n",
        "detector_face_cnn = dlib.cnn_face_detection_model_v1('/content/drive/MyDrive/Visaﾌバ Computacional Guia Completo/Weights/mmod_human_face_detector.dat') # ja eh um modelo treinado para reconhecimento de faces"
      ],
      "metadata": {
        "colab": {
          "base_uri": "https://localhost:8080/",
          "height": 193
        },
        "id": "ICtiBPwlZh_r",
        "outputId": "1bee8695-19c3-4747-ddef-216dae8272db"
      },
      "execution_count": 3,
      "outputs": [
        {
          "output_type": "error",
          "ename": "RuntimeError",
          "evalue": "Error while calling cudaGetDevice(&the_device_id) in file /tmp/.tmpAmKoPO/sdists-v9/pypi/dlib/19.24.6/JxDrwaAs6QBtviDChgF56/src/dlib/cuda/gpu_data.cpp:204. code: 35, reason: CUDA driver version is insufficient for CUDA runtime version",
          "traceback": [
            "\u001b[0;31m---------------------------------------------------------------------------\u001b[0m",
            "\u001b[0;31mRuntimeError\u001b[0m                              Traceback (most recent call last)",
            "\u001b[0;32m<ipython-input-3-f5f94df7ed4d>\u001b[0m in \u001b[0;36m<cell line: 0>\u001b[0;34m()\u001b[0m\n\u001b[1;32m      1\u001b[0m \u001b[0mimagem\u001b[0m \u001b[0;34m=\u001b[0m \u001b[0mcv2\u001b[0m\u001b[0;34m.\u001b[0m\u001b[0mimread\u001b[0m\u001b[0;34m(\u001b[0m\u001b[0;34m'/content/drive/MyDrive/Visaﾌバ Computacional Guia Completo/Images/people2.jpg'\u001b[0m\u001b[0;34m)\u001b[0m\u001b[0;34m\u001b[0m\u001b[0;34m\u001b[0m\u001b[0m\n\u001b[0;32m----> 2\u001b[0;31m \u001b[0mdetector_face_cnn\u001b[0m \u001b[0;34m=\u001b[0m \u001b[0mdlib\u001b[0m\u001b[0;34m.\u001b[0m\u001b[0mcnn_face_detection_model_v1\u001b[0m\u001b[0;34m(\u001b[0m\u001b[0;34m'/content/drive/MyDrive/Visaﾌバ Computacional Guia Completo/Weights/mmod_human_face_detector.dat'\u001b[0m\u001b[0;34m)\u001b[0m \u001b[0;31m# ja eh um modelo treinado para reconhecimento de faces\u001b[0m\u001b[0;34m\u001b[0m\u001b[0;34m\u001b[0m\u001b[0m\n\u001b[0m",
            "\u001b[0;31mRuntimeError\u001b[0m: Error while calling cudaGetDevice(&the_device_id) in file /tmp/.tmpAmKoPO/sdists-v9/pypi/dlib/19.24.6/JxDrwaAs6QBtviDChgF56/src/dlib/cuda/gpu_data.cpp:204. code: 35, reason: CUDA driver version is insufficient for CUDA runtime version"
          ]
        }
      ]
    }
  ]
}